<?xml version="1.0" encoding="utf-8"?>
<!-- This URDF was automatically created by SolidWorks to URDF Exporter! Originally created by Stephen Brawner (brawner@gmail.com) 
     Commit Version: 1.5.1-0-g916b5db  Build Version: 1.5.7152.31018
     For more information, please see http://wiki.ros.org/sw_urdf_exporter -->
<robot
  name="palletizer">
  <link
    name="base_link">
    <inertial>
      <origin
        xyz="-1.5354E-14 -0.029385 1.265"
        rpy="0 0 0" />
      <mass
        value="23.744" />
      <inertia
        ixx="14.085"
        ixy="-2.6176E-17"
        ixz="1.0532E-16"
        iyy="14.191"
        iyz="0.011734"
        izz="0.13257" />
    </inertial>
    <visual>
      <origin
        xyz="0 0 0"
        rpy="0 0 0" />
      <geometry>
        <mesh
          filename="package://palletizer/meshes/base_link.STL" />
      </geometry>
      <material
        name="">
        <color
          rgba="0.50196 0.50196 0.50196 1" />
      </material>
    </visual>
    <collision>
      <origin
        xyz="0 0 0"
        rpy="0 0 0" />
      <geometry>
        <mesh
          filename="package://palletizer/meshes/base_link.STL" />
      </geometry>
    </collision>
  </link>
  <link
    name="Link1">
    <inertial>
      <origin
        xyz="1.1082E-17 -0.13376 -0.084234"
        rpy="0 0 0" />
      <mass
        value="3.2712" />
      <inertia
        ixx="0.035893"
        ixy="-4.9727E-18"
        ixz="-2.6146E-19"
        iyy="0.031004"
        iyz="-0.0090466"
        izz="0.023554" />
    </inertial>
    <visual>
      <origin
        xyz="0 0 0"
        rpy="0 0 0" />
      <geometry>
        <mesh
          filename="package://palletizer/meshes/Link1.STL" />
      </geometry>
      <material
        name="">
        <color
          rgba="1 0 1 1" />
      </material>
    </visual>
    <collision>
      <origin
        xyz="0 0 0"
        rpy="0 0 0" />
      <geometry>
        <mesh
          filename="package://palletizer/meshes/Link1.STL" />
      </geometry>
    </collision>
  </link>
  <joint
    name="Joint1"
    type="prismatic">
    <origin
      xyz="0 0.157 0.572"
      rpy="0 0 0" />
    <parent
      link="base_link" />
    <child
      link="Link1" />
    <axis
      xyz="0 0 1" />
    <limit
      lower="-0.24"
      upper="2.7"
      effort="10000"
      velocity="10000" />
  </joint>
  <link
    name="Link2">
    <inertial>
      <origin
        xyz="0.23082 1.3971E-07 -0.081969"
        rpy="0 0 0" />
      <mass
        value="9.9845" />
      <inertia
        ixx="0.030065"
        ixy="-2.7334E-08"
        ixz="-0.00089423"
        iyy="0.43418"
        iyz="1.1355E-07"
        izz="0.42808" />
    </inertial>
    <visual>
      <origin
        xyz="0 0 0"
        rpy="0 0 0" />
      <geometry>
        <mesh
          filename="package://palletizer/meshes/Link2.STL" />
      </geometry>
      <material
        name="">
        <color
          rgba="0 0 1 1" />
      </material>
    </visual>
    <collision>
      <origin
        xyz="0 0 0"
        rpy="0 0 0" />
      <geometry>
        <mesh
          filename="package://palletizer/meshes/Link2.STL" />
      </geometry>
    </collision>
  </link>
  <joint
    name="Joint2"
    type="revolute">
    <origin
      xyz="0 0 0.193"
      rpy="0 0 0" />
    <parent
      link="Link1" />
    <child
      link="Link2" />
    <axis
      xyz="0 0 1" />
    <limit
      lower="-1"
      upper="4.5"
      effort="10000"
      velocity="10000" />
  </joint>
  <link
    name="Link3">
    <inertial>
      <origin
        xyz="-1.3922E-06 0.25 0.090633"
        rpy="0 0 0" />
      <mass
        value="5.825" />
      <inertia
        ixx="0.21651"
        ixy="-4.1151E-08"
        ixz="1.9765E-08"
        iyy="0.01238"
        iyz="-2.2943E-08"
        izz="0.21124" />
    </inertial>
    <visual>
      <origin
        xyz="0 0 0"
        rpy="0 0 0" />
      <geometry>
        <mesh
          filename="package://palletizer/meshes/Link3.STL" />
      </geometry>
      <material
        name="">
        <color
          rgba="0 1 1 1" />
      </material>
    </visual>
    <collision>
      <origin
        xyz="0 0 0"
        rpy="0 0 0" />
      <geometry>
        <mesh
          filename="package://palletizer/meshes/Link3.STL" />
      </geometry>
    </collision>
  </link>
  <joint
    name="Joint3"
    type="revolute">
    <origin
      xyz="0.5 0 -0.3513"
      rpy="0 0 0" />
    <parent
      link="Link2" />
    <child
      link="Link3" />
    <axis
      xyz="0 0 1" />
    <limit
      lower="-5"
      upper="2.5"
      effort="10000"
      velocity="10000" />
  </joint>
  <link
    name="Link4">
    <inertial>
      <origin
        xyz="3.2259E-07 2.542E-05 -0.08553"
        rpy="0 0 0" />
      <mass
        value="3.9922" />
      <inertia
        ixx="0.019006"
        ixy="3.184E-07"
        ixz="1.9269E-07"
        iyy="0.013834"
        iyz="1.0629E-06"
        izz="0.017104" />
    </inertial>
    <visual>
      <origin
        xyz="0 0 0"
        rpy="0 0 0" />
      <geometry>
        <mesh
          filename="package://palletizer/meshes/Link4.STL" />
      </geometry>
      <material
        name="">
        <color
          rgba="0 1 1 1" />
      </material>
    </visual>
    <collision>
      <origin
        xyz="0 0 0"
        rpy="0 0 0" />
      <geometry>
        <mesh
          filename="package://palletizer/meshes/Link4.STL" />
      </geometry>
    </collision>
  </link>
  <joint
    name="Joint4"
    type="revolute">
    <origin
      xyz="0 0.5 0"
      rpy="0 0 0" />
    <parent
      link="Link3" />
    <child
      link="Link4" />
    <axis
      xyz="0 0 1" />
    <limit
      lower="-3.14"
      upper="3.14"
      effort="10000"
      velocity="10000" />
  </joint>
  <link
    name="Link5">
    <inertial>
      <origin
        xyz="5.003E-08 0.40817 -0.1225"
        rpy="0 0 0" />
      <mass
        value="5.8533" />
      <inertia
        ixx="0.27504"
        ixy="4.3397E-08"
        ixz="-3.2907E-08"
        iyy="0.019709"
        iyz="-8.2924E-05"
        izz="0.28021" />
    </inertial>
    <visual>
      <origin
        xyz="0 0 0"
        rpy="0 0 0" />
      <geometry>
        <mesh
          filename="package://palletizer/meshes/Link5.STL" />
      </geometry>
      <material
        name="">
        <color
          rgba="1 1 0 1" />
      </material>
    </visual>
    <collision>
      <origin
        xyz="0 0 0"
        rpy="0 0 0" />
      <geometry>
        <mesh
          filename="package://palletizer/meshes/Link5.STL" />
      </geometry>
    </collision>
  </link>
  <joint
    name="Joint5"
    type="revolute">
    <origin
      xyz="0 -0.0953 -0.096"
      rpy="0 0 0" />
    <parent
      link="Link4" />
    <child
      link="Link5" />
    <axis
      xyz="0 -1 0" />
    <limit
      lower="-3.14"
      upper="3.14"
      effort="10000"
      velocity="10000" />
  </joint>
  <link
    name="Link6">
    <inertial>
      <origin
        xyz="0 -0.00067297 -0.21469"
        rpy="0 0 0" />
      <mass
        value="2.752" />
      <inertia
        ixx="0.043711"
        ixy="-2.0832E-19"
        ixz="-8.4228E-19"
        iyy="0.043534"
        iyz="-0.00038554"
        izz="0.0031127" />
    </inertial>
    <visual>
      <origin
        xyz="0 0 0"
        rpy="0 0 0" />
      <geometry>
        <mesh
          filename="package://palletizer/meshes/Link6.STL" />
      </geometry>
      <material
        name="">
        <color
          rgba="1 1 0 1" />
      </material>
    </visual>
    <collision>
      <origin
        xyz="0 0 0"
        rpy="0 0 0" />
      <geometry>
        <mesh
          filename="package://palletizer/meshes/Link6.STL" />
      </geometry>
    </collision>
  </link>
  <joint
    name="Joint6"
    type="prismatic">
    <origin
      xyz="0 0.50055 0.326"
      rpy="0 0 0" />
    <parent
      link="Link5" />
    <child
      link="Link6" />
    <axis
      xyz="0 1 0" />
    <limit
      lower="-0.1874"
      upper="0.1874"
      effort="10000"
      velocity="10000" />
  </joint>
  <link
    name="Link7">
    <inertial>
      <origin
        xyz="-5.5511E-17 -0.0022501 -0.16289"
        rpy="0 0 0" />
      <mass
        value="5.3195" />
      <inertia
        ixx="0.047249"
        ixy="5.6013E-18"
        ixz="-1.2454E-17"
        iyy="0.089478"
        iyz="-0.00088103"
        izz="0.046275" />
    </inertial>
    <visual>
      <origin
        xyz="0 0 0"
        rpy="0 0 0" />
      <geometry>
        <mesh
          filename="package://palletizer/meshes/Link7.STL" />
      </geometry>
      <material
        name="">
        <color
          rgba="0 1 0 1" />
      </material>
    </visual>
    <collision>
      <origin
        xyz="0 0 0"
        rpy="0 0 0" />
      <geometry>
        <mesh
          filename="package://palletizer/meshes/Link7.STL" />
      </geometry>
    </collision>
  </link>
  <joint
    name="Joint7"
    type="prismatic">
    <origin
      xyz="0 0.158 -0.023"
      rpy="0 0 0" />
    <parent
      link="Link6" />
    <child
      link="Link7" />
    <axis
      xyz="0 0 1" />
    <limit
      lower="-0.0875"
      upper="0.0875"
      effort="10000"
      velocity="10000" />
  </joint>

<link name="dummy"> 
</link>
<joint name="dummy_joint" type="fixed">
     <parent link="dummy"/>
     <child link="base_link"/>
</joint>
</robot>
